[2023-09-14T03:18:40.699+0000] {taskinstance.py:1157} INFO - Dependencies all met for dep_context=non-requeueable deps ti=<TaskInstance: hearing_news.check_new_posts manual__2023-09-14T03:18:39.798688+00:00 [queued]>
[2023-09-14T03:18:40.707+0000] {taskinstance.py:1157} INFO - Dependencies all met for dep_context=requeueable deps ti=<TaskInstance: hearing_news.check_new_posts manual__2023-09-14T03:18:39.798688+00:00 [queued]>
[2023-09-14T03:18:40.707+0000] {taskinstance.py:1359} INFO - Starting attempt 1 of 1
[2023-09-14T03:18:40.716+0000] {taskinstance.py:1380} INFO - Executing <Task(_PythonDecoratedOperator): check_new_posts> on 2023-09-14 03:18:39.798688+00:00
[2023-09-14T03:18:40.723+0000] {standard_task_runner.py:57} INFO - Started process 379 to run task
[2023-09-14T03:18:40.733+0000] {standard_task_runner.py:84} INFO - Running: ['***', 'tasks', 'run', 'hearing_news', 'check_new_posts', 'manual__2023-09-14T03:18:39.798688+00:00', '--job-id', '19', '--raw', '--subdir', 'DAGS_FOLDER/hearing_news_dag.py', '--cfg-path', '/tmp/tmpkvtn02js']
[2023-09-14T03:18:40.736+0000] {standard_task_runner.py:85} INFO - Job 19: Subtask check_new_posts
[2023-09-14T03:18:40.811+0000] {task_command.py:415} INFO - Running <TaskInstance: hearing_news.check_new_posts manual__2023-09-14T03:18:39.798688+00:00 [running]> on host b3e86375ba74
[2023-09-14T03:18:40.892+0000] {taskinstance.py:1660} INFO - Exporting env vars: AIRFLOW_CTX_DAG_OWNER='***' AIRFLOW_CTX_DAG_ID='hearing_news' AIRFLOW_CTX_TASK_ID='check_new_posts' AIRFLOW_CTX_EXECUTION_DATE='2023-09-14T03:18:39.798688+00:00' AIRFLOW_CTX_TRY_NUMBER='1' AIRFLOW_CTX_DAG_RUN_ID='manual__2023-09-14T03:18:39.798688+00:00'
[2023-09-14T03:18:40.895+0000] {taskinstance.py:1935} ERROR - Task failed with exception
Traceback (most recent call last):
  File "/home/airflow/.local/lib/python3.8/site-packages/airflow/decorators/base.py", line 221, in execute
    return_value = super().execute(context)
  File "/home/airflow/.local/lib/python3.8/site-packages/airflow/operators/python.py", line 192, in execute
    return_value = self.execute_callable()
  File "/home/airflow/.local/lib/python3.8/site-packages/airflow/operators/python.py", line 209, in execute_callable
    return self.python_callable(*self.op_args, **self.op_kwargs)
  File "/opt/airflow/dags/hearing_news_dag.py", line 18, in check_new_posts
    from pymongo.mongo_client import MongoClient
ModuleNotFoundError: No module named 'pymongo'
[2023-09-14T03:18:40.907+0000] {taskinstance.py:1398} INFO - Marking task as FAILED. dag_id=hearing_news, task_id=check_new_posts, execution_date=20230914T031839, start_date=20230914T031840, end_date=20230914T031840
[2023-09-14T03:18:40.917+0000] {standard_task_runner.py:104} ERROR - Failed to execute job 19 for task check_new_posts (No module named 'pymongo'; 379)
[2023-09-14T03:18:40.945+0000] {local_task_job_runner.py:228} INFO - Task exited with return code 1
[2023-09-14T03:18:40.977+0000] {taskinstance.py:2776} INFO - 0 downstream tasks scheduled from follow-on schedule check
