[2023-09-13T19:38:04.763+0000] {taskinstance.py:1157} INFO - Dependencies all met for dep_context=non-requeueable deps ti=<TaskInstance: demo.task_two scheduled__2023-09-12T00:00:00+00:00 [queued]>
[2023-09-13T19:38:04.770+0000] {taskinstance.py:1157} INFO - Dependencies all met for dep_context=requeueable deps ti=<TaskInstance: demo.task_two scheduled__2023-09-12T00:00:00+00:00 [queued]>
[2023-09-13T19:38:04.771+0000] {taskinstance.py:1359} INFO - Starting attempt 1 of 1
[2023-09-13T19:38:04.780+0000] {taskinstance.py:1380} INFO - Executing <Task(_PythonDecoratedOperator): task_two> on 2023-09-12 00:00:00+00:00
[2023-09-13T19:38:04.784+0000] {standard_task_runner.py:57} INFO - Started process 61 to run task
[2023-09-13T19:38:04.790+0000] {standard_task_runner.py:84} INFO - Running: ['***', 'tasks', 'run', 'demo', 'task_two', 'scheduled__2023-09-12T00:00:00+00:00', '--job-id', '13', '--raw', '--subdir', 'DAGS_FOLDER/demo_dag.py', '--cfg-path', '/tmp/tmpeigw49yc']
[2023-09-13T19:38:04.791+0000] {standard_task_runner.py:85} INFO - Job 13: Subtask task_two
[2023-09-13T19:38:04.841+0000] {task_command.py:415} INFO - Running <TaskInstance: demo.task_two scheduled__2023-09-12T00:00:00+00:00 [running]> on host b3e86375ba74
[2023-09-13T19:38:04.916+0000] {taskinstance.py:1660} INFO - Exporting env vars: AIRFLOW_CTX_DAG_OWNER='***' AIRFLOW_CTX_DAG_ID='demo' AIRFLOW_CTX_TASK_ID='task_two' AIRFLOW_CTX_EXECUTION_DATE='2023-09-12T00:00:00+00:00' AIRFLOW_CTX_TRY_NUMBER='1' AIRFLOW_CTX_DAG_RUN_ID='scheduled__2023-09-12T00:00:00+00:00'
[2023-09-13T19:38:04.918+0000] {taskinstance.py:1935} ERROR - Task failed with exception
Traceback (most recent call last):
  File "/home/airflow/.local/lib/python3.8/site-packages/airflow/decorators/base.py", line 221, in execute
    return_value = super().execute(context)
  File "/home/airflow/.local/lib/python3.8/site-packages/airflow/operators/python.py", line 192, in execute
    return_value = self.execute_callable()
  File "/home/airflow/.local/lib/python3.8/site-packages/airflow/operators/python.py", line 209, in execute_callable
    return self.python_callable(*self.op_args, **self.op_kwargs)
  File "/opt/airflow/dags/demo_dag.py", line 21, in task_two
    return input[0] + 10
TypeError: can only concatenate str (not "int") to str
[2023-09-13T19:38:04.928+0000] {taskinstance.py:1398} INFO - Marking task as FAILED. dag_id=demo, task_id=task_two, execution_date=20230912T000000, start_date=20230913T193804, end_date=20230913T193804
[2023-09-13T19:38:04.937+0000] {standard_task_runner.py:104} ERROR - Failed to execute job 13 for task task_two (can only concatenate str (not "int") to str; 61)
[2023-09-13T19:38:04.961+0000] {local_task_job_runner.py:228} INFO - Task exited with return code 1
[2023-09-13T19:38:04.978+0000] {taskinstance.py:2776} INFO - 0 downstream tasks scheduled from follow-on schedule check
